Workbook

Sheet Leia-me
A1: Lead Scoring de Oportunidades: protótipo
A3: Objetivo | B3: Priorizar as oportunidades abertas (Engaging e Prospecting) por valor e momento no ciclo, e sinalizar as paradas para reciclagem.
A4: Fórmula | B4: Score = (Pontos de valor + Pontos de tempo) × Multiplicador de reciclagem, de 0 a 100.
A5: Pontos de valor (0–60) | B5: Preço de lista do produto em escala logarítmica. Ver a aba Parâmetros.
A6: Pontos de tempo (0–40) | B6: Dias em Engaging até a data de referência. Prospecting recebe pontuação fixa.
A7: Multiplicador | B7: Aplicado só às oportunidades paradas (mais dias que o limite de ciclo). Elas vão para a faixa R (Reciclar).
A8: Faixas | B8: A / B / C / D para as oportunidades ativas, conforme os cortes de score; R para as paradas.
A10: Como usar
A11: 1. Parâmetros | B11: Edite só as células amarelas com texto azul. Todo o resto recalcula.
A12: 2. Pipeline | B12: Oportunidades abertas já pontuadas. Use o filtro do cabeçalho para ver uma fila (ex.: Faixa = A) ou um vendedor.
A13: 3. Resumo | B13: Distribuição por faixa, por produto e por vendedor. Atualiza sozinho.
A14: 4. Histórico | B14: Negócios fechados (Won/Lost), base das taxas de ganho por tempo de ciclo mostradas em Parâmetros.
A16: Convenções | B16: Texto azul em fundo amarelo = premissa editável. Texto preto = fórmula. Verde = referência a outra aba.
A17: Premissas | B17: Data de referência 31/12/2017 (última data dos arquivos). "GTXPro" foi normalizado para "GTX Pro". O valor usado é o preço de lista, porque os negócios fecham em média a ~100% dele.
A18: Por que não há fit da conta | B18: Setor, porte, receita, país, produto e vendedor não mostraram poder preditivo sobre o ganho (lift entre 0,95 e 1,05; AUC fora do tempo ~0,50). Por isso não entram no score.
A19: Google Sheets | B19: Arquivo → Importar → Fazer upload, ou abra o .xlsx pelo Drive e use Arquivo → Salvar como Planilhas Google.

Sheet Resumo
A1: Resumo do pipeline pontuado
A2: ="Oportunidades abertas: "&COUNTA(Pipeline!$A$2:$A$2090)&" | Data de referência: "&TEXT(Parâmetros!B5,"dd/mm/yyyy") -> Oportunidades abertas: 2089 | Data de referência: 31/12/2017
A4: Faixa | B4: Oportunidades | C4: % das oportunidades | D4: Pipeline (US$, preço de lista) | E4: % do pipeline | F4: Sem conta preenchida | G4: Ação recomendada
A5: A | B5: =COUNTIF(Pipeline!$P$2:$P$2090,A5) -> 112 | C5: =IFERROR(B5/$B$10,0) -> 0.053614169 | D5: =SUMIF(Pipeline!$P$2:$P$2090,A5,Pipeline!$I$2:$I$2090) -> 555707 | E5: =IFERROR(D5/$D$10,0) -> 0.11189749 | F5: =COUNTIFS(Pipeline!$P$2:$P$2090,A5,Pipeline!$Q$2:$Q$2090,"Completar cadastro") -> 84 | G5: =INDEX(Parâmetros!$D$39:$D$43,MATCH(A5,Parâmetros!$A$39:$A$43,0)) -> Prioridade máxima: próximo passo em até 48h
A6: B | B6: =COUNTIF(Pipeline!$P$2:$P$2090,A6) -> 148 | C6: =IFERROR(B6/$B$10,0) -> 0.070847295 | D6: =SUMIF(Pipeline!$P$2:$P$2090,A6,Pipeline!$I$2:$I$2090) -> 378906 | E6: =IFERROR(D6/$D$10,0) -> 0.076296737 | F6: =COUNTIFS(Pipeline!$P$2:$P$2090,A6,Pipeline!$Q$2:$Q$2090,"Completar cadastro") -> 100 | G6: =INDEX(Parâmetros!$D$39:$D$43,MATCH(A6,Parâmetros!$A$39:$A$43,0)) -> Cadência padrão
A7: C | B7: =COUNTIF(Pipeline!$P$2:$P$2090,A7) -> 299 | C7: =IFERROR(B7/$B$10,0) -> 0.14313068 | D7: =SUMIF(Pipeline!$P$2:$P$2090,A7,Pipeline!$I$2:$I$2090) -> 773758 | E7: =IFERROR(D7/$D$10,0) -> 0.15580437 | F7: =COUNTIFS(Pipeline!$P$2:$P$2090,A7,Pipeline!$Q$2:$Q$2090,"Completar cadastro") -> 196 | G7: =INDEX(Parâmetros!$D$39:$D$43,MATCH(A7,Parâmetros!$A$39:$A$43,0)) -> Cadência leve, foco em qualificar
A8: D | B8: =COUNTIF(Pipeline!$P$2:$P$2090,A8) -> 239 | C8: =IFERROR(B8/$B$10,0) -> 0.11440881 | D8: =SUMIF(Pipeline!$P$2:$P$2090,A8,Pipeline!$I$2:$I$2090) -> 59180 | E8: =IFERROR(D8/$D$10,0) -> 0.01191652 | F8: =COUNTIFS(Pipeline!$P$2:$P$2090,A8,Pipeline!$Q$2:$Q$2090,"Completar cadastro") -> 166 | G8: =INDEX(Parâmetros!$D$39:$D$43,MATCH(A8,Parâmetros!$A$39:$A$43,0)) -> Automatizar ou vender em lote
A9: R | B9: =COUNTIF(Pipeline!$P$2:$P$2090,A9) -> 1291 | C9: =IFERROR(B9/$B$10,0) -> 0.61799904 | D9: =SUMIF(Pipeline!$P$2:$P$2090,A9,Pipeline!$I$2:$I$2090) -> 3198664 | E9: =IFERROR(D9/$D$10,0) -> 0.64408488 | F9: =COUNTIFS(Pipeline!$P$2:$P$2090,A9,Pipeline!$Q$2:$Q$2090,"Completar cadastro") -> 879 | G9: =INDEX(Parâmetros!$D$39:$D$43,MATCH(A9,Parâmetros!$A$39:$A$43,0)) -> Reciclar: requalificar, reengajar ou encerrar
A10: Total | B10: =SUM(B5:B9) -> 2089 | C10: =SUM(C5:C9) -> 1 | D10: =SUM(D5:D9) -> 4966215 | E10: =SUM(E5:E9) -> 1 | F10: =SUM(F5:F9) -> 1425
A11: % da faixa A entre as ativas (meta: 15–20%) | C11: =IFERROR(B5/SUM(B5:B8),0) -> 0.14035088
A13: Produto | B13: A | C13: B | D13: C | E13: D | F13: R | G13: Total
A14: GTK 500 | B14: =COUNTIFS(Pipeline!$E$2:$E$2090,$A14,Pipeline!$P$2:$P$2090,"A") -> 1 | C14: =COUNTIFS(Pipeline!$E$2:$E$2090,$A14,Pipeline!$P$2:$P$2090,"B") -> 0 | D14: =COUNTIFS(Pipeline!$E$2:$E$2090,$A14,Pipeline!$P$2:$P$2090,"C") -> 0 | E14: =COUNTIFS(Pipeline!$E$2:$E$2090,$A14,Pipeline!$P$2:$P$2090,"D") -> 0 | F14: =COUNTIFS(Pipeline!$E$2:$E$2090,$A14,Pipeline!$P$2:$P$2090,"R") -> 14 | G14: =SUM(B14:F14) -> 15
A15: GTX Plus Pro | B15: =COUNTIFS(Pipeline!$E$2:$E$2090,$A15,Pipeline!$P$2:$P$2090,"A") -> 36 | C15: =COUNTIFS(Pipeline!$E$2:$E$2090,$A15,Pipeline!$P$2:$P$2090,"B") -> 48 | D15: =COUNTIFS(Pipeline!$E$2:$E$2090,$A15,Pipeline!$P$2:$P$2090,"C") -> 0 | E15: =COUNTIFS(Pipeline!$E$2:$E$2090,$A15,Pipeline!$P$2:$P$2090,"D") -> 0 | F15: =COUNTIFS(Pipeline!$E$2:$E$2090,$A15,Pipeline!$P$2:$P$2090,"R") -> 139 | G15: =SUM(B15:F15) -> 223
A16: GTX Pro | B16: =COUNTIFS(Pipeline!$E$2:$E$2090,$A16,Pipeline!$P$2:$P$2090,"A") -> 54 | C16: =COUNTIFS(Pipeline!$E$2:$E$2090,$A16,Pipeline!$P$2:$P$2090,"B") -> 2 | D16: =COUNTIFS(Pipeline!$E$2:$E$2090,$A16,Pipeline!$P$2:$P$2090,"C") -> 80 | E16: =COUNTIFS(Pipeline!$E$2:$E$2090,$A16,Pipeline!$P$2:$P$2090,"D") -> 0 | F16: =COUNTIFS(Pipeline!$E$2:$E$2090,$A16,Pipeline!$P$2:$P$2090,"R") -> 197 | G16: =SUM(B16:F16) -> 333
A17: MG Advanced | B17: =COUNTIFS(Pipeline!$E$2:$E$2090,$A17,Pipeline!$P$2:$P$2090,"A") -> 21 | C17: =COUNTIFS(Pipeline!$E$2:$E$2090,$A17,Pipeline!$P$2:$P$2090,"B") -> 8 | D17: =COUNTIFS(Pipeline!$E$2:$E$2090,$A17,Pipeline!$P$2:$P$2090,"C") -> 86 | E17: =COUNTIFS(Pipeline!$E$2:$E$2090,$A17,Pipeline!$P$2:$P$2090,"D") -> 0 | F17: =COUNTIFS(Pipeline!$E$2:$E$2090,$A17,Pipeline!$P$2:$P$2090,"R") -> 213 | G17: =SUM(B17:F17) -> 328
A18: GTX Plus Basic | B18: =COUNTIFS(Pipeline!$E$2:$E$2090,$A18,Pipeline!$P$2:$P$2090,"A") -> 0 | C18: =COUNTIFS(Pipeline!$E$2:$E$2090,$A18,Pipeline!$P$2:$P$2090,"B") -> 54 | D18: =COUNTIFS(Pipeline!$E$2:$E$2090,$A18,Pipeline!$P$2:$P$2090,"C") -> 75 | E18: =COUNTIFS(Pipeline!$E$2:$E$2090,$A18,Pipeline!$P$2:$P$2090,"D") -> 0 | F18: =COUNTIFS(Pipeline!$E$2:$E$2090,$A18,Pipeline!$P$2:$P$2090,"R") -> 203 | G18: =SUM(B18:F18) -> 332
A19: GTX Basic | B19: =COUNTIFS(Pipeline!$E$2:$E$2090,$A19,Pipeline!$P$2:$P$2090,"A") -> 0 | C19: =COUNTIFS(Pipeline!$E$2:$E$2090,$A19,Pipeline!$P$2:$P$2090,"B") -> 36 | D19: =COUNTIFS(Pipeline!$E$2:$E$2090,$A19,Pipeline!$P$2:$P$2090,"C") -> 22 | E19: =COUNTIFS(Pipeline!$E$2:$E$2090,$A19,Pipeline!$P$2:$P$2090,"D") -> 93 | F19: =COUNTIFS(Pipeline!$E$2:$E$2090,$A19,Pipeline!$P$2:$P$2090,"R") -> 279 | G19: =SUM(B19:F19) -> 430
A20: MG Special | B20: =COUNTIFS(Pipeline!$E$2:$E$2090,$A20,Pipeline!$P$2:$P$2090,"A") -> 0 | C20: =COUNTIFS(Pipeline!$E$2:$E$2090,$A20,Pipeline!$P$2:$P$2090,"B") -> 0 | D20: =COUNTIFS(Pipeline!$E$2:$E$2090,$A20,Pipeline!$P$2:$P$2090,"C") -> 36 | E20: =COUNTIFS(Pipeline!$E$2:$E$2090,$A20,Pipeline!$P$2:$P$2090,"D") -> 146 | F20: =COUNTIFS(Pipeline!$E$2:$E$2090,$A20,Pipeline!$P$2:$P$2090,"R") -> 246 | G20: =SUM(B20:F20) -> 428
A22: Por vendedor (ordenado por gerente)
A23: Vendedor | B23: Gerente | C23: A | D23: B | E23: C | F23: D | G23: R | H23: Total | I23: Pipeline A+B (US$)
A24: Corliss Cosme | B24: Cara Losch | C24: =COUNTIFS(Pipeline!$B$2:$B$2090,$A24,Pipeline!$P$2:$P$2090,"A") -> 10 | D24: =COUNTIFS(Pipeline!$B$2:$B$2090,$A24,Pipeline!$P$2:$P$2090,"B") -> 4 | E24: =COUNTIFS(Pipeline!$B$2:$B$2090,$A24,Pipeline!$P$2:$P$2090,"C") -> 2 | F24: =COUNTIFS(Pipeline!$B$2:$B$2090,$A24,Pipeline!$P$2:$P$2090,"D") -> 2 | G24: =COUNTIFS(Pipeline!$B$2:$B$2090,$A24,Pipeline!$P$2:$P$2090,"R") -> 63 | H24: =SUM(C24:G24) -> 81 | I24: =SUMIFS(Pipeline!$I$2:$I$2090,Pipeline!$B$2:$B$2090,$A24,Pipeline!$P$2:$P$2090,"A")+SUMIFS(Pipeline!$I$2:$I$2090,Pipeline!$B$2:$B$2090,$A24,Pipeline!$P$2:$P$2090,"B") -> 55676
A25: Elizabeth Anderson | B25: Cara Losch | C25: =COUNTIFS(Pipeline!$B$2:$B$2090,$A25,Pipeline!$P$2:$P$2090,"A") -> 0 | D25: =COUNTIFS(Pipeline!$B$2:$B$2090,$A25,Pipeline!$P$2:$P$2090,"B") -> 0 | E25: =COUNTIFS(Pipeline!$B$2:$B$2090,$A25,Pipeline!$P$2:$P$2090,"C") -> 0 | F25: =COUNTIFS(Pipeline!$B$2:$B$2090,$A25,Pipeline!$P$2:$P$2090,"D") -> 0 | G25: =COUNTIFS(Pipeline!$B$2:$B$2090,$A25,Pipeline!$P$2:$P$2090,"R") -> 0 | H25: =SUM(C25:G25) -> 0 | I25: =SUMIFS(Pipeline!$I$2:$I$2090,Pipeline!$B$2:$B$2090,$A25,Pipeline!$P$2:$P$2090,"A")+SUMIFS(Pipeline!$I$2:$I$2090,Pipeline!$B$2:$B$2090,$A25,Pipeline!$P$2:$P$2090,"B") -> 0
A26: Garret Kinder | B26: Cara Losch | C26: =COUNTIFS(Pipeline!$B$2:$B$2090,$A26,Pipeline!$P$2:$P$2090,"A") -> 0 | D26: =COUNTIFS(Pipeline!$B$2:$B$2090,$A26,Pipeline!$P$2:$P$2090,"B") -> 0 | E26: =COUNTIFS(Pipeline!$B$2:$B$2090,$A26,Pipeline!$P$2:$P$2090,"C") -> 0 | F26: =COUNTIFS(Pipeline!$B$2:$B$2090,$A26,Pipeline!$P$2:$P$2090,"D") -> 0 | G26: =COUNTIFS(Pipeline!$B$2:$B$2090,$A26,Pipeline!$P$2:$P$2090,"R") -> 0 | H26: =SUM(C26:G26) -> 0 | I26: =SUMIFS(Pipeline!$I$2:$I$2090,Pipeline!$B$2:$B$2090,$A26,Pipeline!$P$2:$P$2090,"A")+SUMIFS(Pipeline!$I$2:$I$2090,Pipeline!$B$2:$B$2090,$A26,Pipeline!$P$2:$P$2090,"B") -> 0
A27: Rosie Papadopoulos | B27: Cara Losch | C27: =COUNTIFS(Pipeline!$B$2:$B$2090,$A27,Pipeline!$P$2:$P$2090,"A") -> 5 | D27: =COUNTIFS(Pipeline!$B$2:$B$2090,$A27,Pipeline!$P$2:$P$2090,"B") -> 1 | E27: =COUNTIFS(Pipeline!$B$2:$B$2090,$A27,Pipeline!$P$2:$P$2090,"C") -> 0 | F27: =COUNTIFS(Pipeline!$B$2:$B$2090,$A27,Pipeline!$P$2:$P$2090,"D") -> 0 | G27: =COUNTIFS(Pipeline!$B$2:$B$2090,$A27,Pipeline!$P$2:$P$2090,"R") -> 33 | H27: =SUM(C27:G27) -> 39 | I27: =SUMIFS(Pipeline!$I$2:$I$2090,Pipeline!$B$2:$B$2090,$A27,Pipeline!$P$2:$P$2090,"A")+SUMIFS(Pipeline!$I$2:$I$2090,Pipeline!$B$2:$B$2090,$A27,Pipeline!$P$2:$P$2090,"B") -> 23227
A28: Violet Mclelland | B28: Cara Losch | C28: =COUNTIFS(Pipeline!$B$2:$B$2090,$A28,Pipeline!$P$2:$P$2090,"A") -> 2 | D28: =COUNTIFS(Pipeline!$B$2:$B$2090,$A28,Pipeline!$P$2:$P$2090,"B") -> 4 | E28: =COUNTIFS(Pipeline!$B$2:$B$2090,$A28,Pipeline!$P$2:$P$2090,"C") -> 5 | F28: =COUNTIFS(Pipeline!$B$2:$B$2090,$A28,Pipeline!$P$2:$P$2090,"D") -> 6 | G28: =COUNTIFS(Pipeline!$B$2:$B$2090,$A28,Pipeline!$P$2:$P$2090,"R") -> 51 | H28: =SUM(C28:G28) -> 68 | I28: =SUMIFS(Pipeline!$I$2:$I$2090,Pipeline!$B$2:$B$2090,$A28,Pipeline!$P$2:$P$2090,"A")+SUMIFS(Pipeline!$I$2:$I$2090,Pipeline!$B$2:$B$2090,$A28,Pipeline!$P$2:$P$2090,"B") -> 11506
A29: Wilburn Farren | B29: Cara Losch | C29: =COUNTIFS(Pipeline!$B$2:$B$2090,$A29,Pipeline!$P$2:$P$2090,"A") -> 6 | D29: =COUNTIFS(Pipeline!$B$2:$B$2090,$A29,Pipeline!$P$2:$P$2090,"B") -> 1 | E29: =COUNTIFS(Pipeline!$B$2:$B$2090,$A29,Pipeline!$P$2:$P$2090,"C") -> 2 | F29: =COUNTIFS(Pipeline!$B$2:$B$2090,$A29,Pipeline!$P$2:$P$2090,"D") -> 0 | G29: =COUNTIFS(Pipeline!$B$2:$B$2090,$A29,Pipeline!$P$2:$P$2090,"R") -> 22 | H29: =SUM(C29:G29) -> 31 | I29: =SUMIFS(Pipeline!$I$2:$I$2090,Pipeline!$B$2:$B$2090,$A29,Pipeline!$P$2:$P$2090,"A")+SUMIFS(Pipeline!$I$2:$I$2090,Pipeline!$B$2:$B$2090,$A29,Pipeline!$P$2:$P$2090,"B") -> 29149
A30: Carol Thompson | B30: Celia Rouche | C30: =COUNTIFS(Pipeline!$B$2:$B$2090,$A30,Pipeline!$P$2:$P$2090,"A") -> 0 | D30: =COUNTIFS(Pipeline!$B$2:$B$2090,$A30,Pipeline!$P$2:$P$2090,"B") -> 0 | E30: =COUNTIFS(Pipeline!$B$2:$B$2090,$A30,Pipeline!$P$2:$P$2090,"C") -> 0 | F30: =COUNTIFS(Pipeline!$B$2:$B$2090,$A30,Pipeline!$P$2:$P$2090,"D") -> 0 | G30: =COUNTIFS(Pipeline!$B$2:$B$2090,$A30,Pipeline!$P$2:$P$2090,"R") -> 0 | H30: =SUM(C30:G30) -> 0 | I30: =SUMIFS(Pipeline!$I$2:$I$2090,Pipeline!$B$2:$B$2090,$A30,Pipeline!$P$2:$P$2090,"A")+SUMIFS(Pipeline!$I$2:$I$2090,Pipeline!$B$2:$B$2090,$A30,Pipeline!$P$2:$P$2090,"B") -> 0
A31: Elease Gluck | B31: Celia Rouche | C31: =COUNTIFS(Pipeline!$B$2:$B$2090,$A31,Pipeline!$P$2:$P$2090,"A") -> 4 | D31: =COUNTIFS(Pipeline!$B$2:$B$2090,$A31,Pipeline!$P$2:$P$2090,"B") -> 1 | E31: =COUNTIFS(Pipeline!$B$2:$B$2090,$A31,Pipeline!$P$2:$P$2090,"C") -> 3 | F31: =COUNTIFS(Pipeline!$B$2:$B$2090,$A31,Pipeline!$P$2:$P$2090,"D") -> 4 | G31: =COUNTIFS(Pipeline!$B$2:$B$2090,$A31,Pipeline!$P$2:$P$2090,"R") -> 39 | H31: =SUM(C31:G31) -> 51 | I31: =SUMIFS(Pipeline!$I$2:$I$2090,Pipeline!$B$2:$B$2090,$A31,Pipeline!$P$2:$P$2090,"A")+SUMIFS(Pipeline!$I$2:$I$2090,Pipeline!$B$2:$B$2090,$A31,Pipeline!$P$2:$P$2090,"B") -> 20274
A32: Hayden Neloms | B32: Celia Rouche | C32: =COUNTIFS(Pipeline!$B$2:$B$2090,$A32,Pipeline!$P$2:$P$2090,"A") -> 2 | D32: =COUNTIFS(Pipeline!$B$2:$B$2090,$A32,Pipeline!$P$2:$P$2090,"B") -> 1 | E32: =COUNTIFS(Pipeline!$B$2:$B$2090,$A32,Pipeline!$P$2:$P$2090,"C") -> 1 | F32: =COUNTIFS(Pipeline!$B$2:$B$2090,$A32,Pipeline!$P$2:$P$2090,"D") -> 2 | G32: =COUNTIFS(Pipeline!$B$2:$B$2090,$A32,Pipeline!$P$2:$P$2090,"R") -> 44 | H32: =SUM(C32:G32) -> 50 | I32: =SUMIFS(Pipeline!$I$2:$I$2090,Pipeline!$B$2:$B$2090,$A32,Pipeline!$P$2:$P$2090,"A")+SUMIFS(Pipeline!$I$2:$I$2090,Pipeline!$B$2:$B$2090,$A32,Pipeline!$P$2:$P$2090,"B") -> 9971
A33: Markita Hansen | B33: Celia Rouche | C33: =COUNTIFS(Pipeline!$B$2:$B$2090,$A33,Pipeline!$P$2:$P$2090,"A") -> 5 | D33: =COUNTIFS(Pipeline!$B$2:$B$2090,$A33,Pipeline!$P$2:$P$2090,"B") -> 5 | E33: =COUNTIFS(Pipeline!$B$2:$B$2090,$A33,Pipeline!$P$2:$P$2090,"C") -> 4 | F33: =COUNTIFS(Pipeline!$B$2:$B$2090,$A33,Pipeline!$P$2:$P$2090,"D") -> 5 | G33: =COUNTIFS(Pipeline!$B$2:$B$2090,$A33,Pipeline!$P$2:$P$2090,"R") -> 60 | H33: =SUM(C33:G33) -> 79 | I33: =SUMIFS(Pipeline!$I$2:$I$2090,Pipeline!$B$2:$B$2090,$A33,Pipeline!$P$2:$P$2090,"A")+SUMIFS(Pipeline!$I$2:$I$2090,Pipeline!$B$2:$B$2090,$A33,Pipeline!$P$2:$P$2090,"B") -> 31115
A34: Rosalina Dieter | B34: Celia Rouche | C34: =COUNTIFS(Pipeline!$B$2:$B$2090,$A34,Pipeline!$P$2:$P$2090,"A") -> 2 | D34: =COUNTIFS(Pipeline!$B$2:$B$2090,$A34,Pipeline!$P$2:$P$2090,"B") -> 2 | E34: =COUNTIFS(Pipeline!$B$2:$B$2090,$A34,Pipeline!$P$2:$P$2090,"C") -> 9 | F34: =COUNTIFS(Pipeline!$B$2:$B$2090,$A34,Pipeline!$P$2:$P$2090,"D") -> 3 | G34: =COUNTIFS(Pipeline!$B$2:$B$2090,$A34,Pipeline!$P$2:$P$2090,"R") -> 34 | H34: =SUM(C34:G34) -> 50 | I34: =SUMIFS(Pipeline!$I$2:$I$2090,Pipeline!$B$2:$B$2090,$A34,Pipeline!$P$2:$P$2090,"A")+SUMIFS(Pipeline!$I$2:$I$2090,Pipeline!$B$2:$B$2090,$A34,Pipeline!$P$2:$P$2090,"B") -> 36078
A35: Vicki Laflamme | B35: Celia Rouche | C35: =COUNTIFS(Pipeline!$B$2:$B$2090,$A35,Pipeline!$P$2:$P$2090,"A") -> 10 | D35: =COUNTIFS(Pipeline!$B$2:$B$2090,$A35,Pipeline!$P$2:$P$2090,"B") -> 4 | E35: =COUNTIFS(Pipeline!$B$2:$B$2090,$A35,Pipeline!$P$2:$P$2090,"C") -> 9 | F35: =COUNTIFS(Pipeline!$B$2:$B$2090,$A35,Pipeline!$P$2:$P$2090,"D") -> 1 | G35: =COUNTIFS(Pipeline!$B$2:$B$2090,$A35,Pipeline!$P$2:$P$2090,"R") -> 80 | H35: =SUM(C35:G35) -> 104 | I35: =SUMIFS(Pipeline!$I$2:$I$2090,Pipeline!$B$2:$B$2090,$A35,Pipeline!$P$2:$P$2090,"A")+SUMIFS(Pipeline!$I$2:$I$2090,Pipeline!$B$2:$B$2090,$A35,Pipeline!$P$2:$P$2090,"B") -> 49977
... A58: Zane Levy | B58: Summer Sewald | C58: =COUNTIFS(Pipeline!$B$2:$B$2090,$A58,Pipeline!$P$2:$P$2090,"A") -> 11 | D58: =COUNTIFS(Pipeline!$B$2:$B$2090,$A58,Pipeline!$P$2:$P$2090,"B") -> 12 | E58: =COUNTIFS(Pipeline!$B$2:$B$2090,$A58,Pipeline!$P$2:$P$2090,"C") -> 7 | F58: =COUNTIFS(Pipeline!$B$2:$B$2090,$A58,Pipeline!$P$2:$P$2090,"D") -> 1 | G58: =COUNTIFS(Pipeline!$B$2:$B$2090,$A58,Pipeline!$P$2:$P$2090,"R") -> 57 | H58: =SUM(C58:G58) -> 88 | I58: =SUMIFS(Pipeline!$I$2:$I$2090,Pipeline!$B$2:$B$2090,$A58,Pipeline!$P$2:$P$2090,"A")+SUMIFS(Pipeline!$I$2:$I$2090,Pipeline!$B$2:$B$2090,$A58,Pipeline!$P$2:$P$2090,"B") -> 62916

Sheet Parâmetros
A1: Parâmetros do modelo
A2: Edite só as células amarelas (texto azul). O resto recalcula.
A4: Gerais
A5: Data de referência | B5: 43100
A6: Limite de ciclo (dias) → parado | B6: 138
A7: Ciclo máximo no histórico (referência) | B7: =MAX(Histórico!$H$2:$H$6712) -> 138
A8: Pontos máximos de valor | B8: 60
A9: Pontos fixos para Prospecting | B9: 10
A11: Pontos de valor por produto
A12: Produto | B12: Série | C12: Preço de lista (US$) | D12: Pontos de valor
A13: MG Special | B13: MG | C13: 55 | D13: =ROUND($B$8*(LN(C13)-LN(MIN($C$13:$C$19)))/(LN(MAX($C$13:$C$19))-LN(MIN($C$13:$C$19))),0) -> 0
A14: GTX Basic | B14: GTX | C14: 550 | D14: =ROUND($B$8*(LN(C14)-LN(MIN($C$13:$C$19)))/(LN(MAX($C$13:$C$19))-LN(MIN($C$13:$C$19))),0) -> 22
A15: GTX Plus Basic | B15: GTX | C15: 1096 | D15: =ROUND($B$8*(LN(C15)-LN(MIN($C$13:$C$19)))/(LN(MAX($C$13:$C$19))-LN(MIN($C$13:$C$19))),0) -> 29
A16: MG Advanced | B16: MG | C16: 3393 | D16: =ROUND($B$8*(LN(C16)-LN(MIN($C$13:$C$19)))/(LN(MAX($C$13:$C$19))-LN(MIN($C$13:$C$19))),0) -> 40
A17: GTX Pro | B17: GTX | C17: 4821 | D17: =ROUND($B$8*(LN(C17)-LN(MIN($C$13:$C$19)))/(LN(MAX($C$13:$C$19))-LN(MIN($C$13:$C$19))),0) -> 43
A18: GTX Plus Pro | B18: GTX | C18: 5482 | D18: =ROUND($B$8*(LN(C18)-LN(MIN($C$13:$C$19)))/(LN(MAX($C$13:$C$19))-LN(MIN($C$13:$C$19))),0) -> 45
A19: GTK 500 | B19: GTK | C19: 26768 | D19: =ROUND($B$8*(LN(C19)-LN(MIN($C$13:$C$19)))/(LN(MAX($C$13:$C$19))-LN(MIN($C$13:$C$19))),0) -> 60
A20: Escala logarítmica: o produto mais barato recebe 0 e o mais caro recebe o máximo.
A22: Pontos de tempo (oportunidades em Engaging)
A23: A partir de (dias) | B23: Até (dias) | C23: Pontos de tempo | D23: Taxa de ganho histórica | E23: Negócios no histórico | F23: Racional
A24: 0 | B24: =A25-1 -> 14 | C24: 20 | D24: =IFERROR(COUNTIFS(Histórico!$H$2:$H$6712,">="&A24,Histórico!$H$2:$H$6712,"<="&B24,Histórico!$I$2:$I$6712,1)/COUNTIFS(Histórico!$H$2:$H$6712,">="&A24,Histórico!$H$2:$H$6712,"<="&B24),0) -> 0.55488239 | E24: =COUNTIFS(Histórico!$H$2:$H$6712,">="&A24,Histórico!$H$2:$H$6712,"<="&B24) -> 2806 | F24: Fase de mais perdas
A25: 15 | B25: =A26-1 -> 90 | C25: 32 | D25: =IFERROR(COUNTIFS(Histórico!$H$2:$H$6712,">="&A25,Histórico!$H$2:$H$6712,"<="&B25,Histórico!$I$2:$I$6712,1)/COUNTIFS(Histórico!$H$2:$H$6712,">="&A25,Histórico!$H$2:$H$6712,"<="&B25),0) -> 0.67334119 | E25: =COUNTIFS(Histórico!$H$2:$H$6712,">="&A25,Histórico!$H$2:$H$6712,"<="&B25) -> 2547 | F25: Ganho estabiliza em ~2/3
A26: 91 | B26: =$B$6 -> 138 | C26: 40 | D26: =IFERROR(COUNTIFS(Histórico!$H$2:$H$6712,">="&A26,Histórico!$H$2:$H$6712,"<="&B26,Histórico!$I$2:$I$6712,1)/COUNTIFS(Histórico!$H$2:$H$6712,">="&A26,Histórico!$H$2:$H$6712,"<="&B26),0) -> 0.71134021 | E26: =COUNTIFS(Histórico!$H$2:$H$6712,">="&A26,Histórico!$H$2:$H$6712,"<="&B26) -> 1358 | F26: Fase de decisão, maior taxa de ganho
A27: =$B$6+1 -> 139 | B27: (sem limite) | C27: 0 | D27: n/a | E27: n/a | F27: Parado: acima do limite de ciclo → faixa R
A28: Faixa geral: | C28: Taxa média de ganho: | D28: =AVERAGE(Histórico!$I$2:$I$6712) -> 0.63150052
A30: Multiplicador de reciclagem (oportunidades paradas)
A31: A partir de (dias) | B31: Até (dias) | C31: Multiplicador | D31: Observação
A32: 0 | B32: =$B$6 -> 138 | C32: 1 | D32: Ativa: sem penalidade
A33: =$B$6+1 -> 139 | B33: =A34-1 -> 180 | C33: 0.6 | D33: Parada recente: reengajar
A34: 181 | B34: =A35-1 -> 270 | C34: 0.4 | D34: Requalificar
A35: 271 | B35: (sem limite) | C35: 0.25 | D35: Avaliar encerramento
A37: Faixas e ações
A38: Faixa | B38: Score mínimo | C38: Critério | D38: Ação recomendada
A39: A | B39: 75 | C39: Ativa, score ≥ corte A | D39: Prioridade máxima: próximo passo em até 48h
A40: B | B40: 55 | C40: Ativa, score ≥ corte B | D40: Cadência padrão
A41: C | B41: 35 | C41: Ativa, score ≥ corte C | D41: Cadência leve, foco em qualificar
A42: D | B42: 0 | C42: Ativa, abaixo do corte C | D42: Automatizar ou vender em lote
A43: R | B43: n/a | C43: Parada (dias > limite de ciclo) | D43: Reciclar: requalificar, reengajar ou encerrar

Sheet Pipeline
A1: ID | B1: Vendedor | C1: Gerente | D1: Regional | E1: Produto | F1: Conta | G1: Estágio | H1: Data engajamento | I1: Preço de lista (US$) | J1: Dias em Engaging | K1: Pontos valor | L1: Pontos tempo | M1: Multiplicador | N1: Score | O1: Parada? | P1: Faixa | Q1: Alerta cadastro | R1: Ação recomendada
A2: 1LY8CAXD | B2: Rosalina Dieter | C2: Celia Rouche | D2: West | E2: GTK 500 | F2: Betasoloin | G2: Engaging | H2: 43005 | I2: =INDEX(Parâmetros!$C$13:$C$19,MATCH(E2,Parâmetros!$A$13:$A$19,0)) -> 26768 | J2: =IF(H2="","",Parâmetros!$B$5-H2) -> 95 | K2: =INDEX(Parâmetros!$D$13:$D$19,MATCH(E2,Parâmetros!$A$13:$A$19,0)) -> 60 | L2: =IF(G2="Prospecting",Parâmetros!$B$9,IF(J2>Parâmetros!$B$6,0,INDEX(Parâmetros!$C$24:$C$26,MATCH(J2,Parâmetros!$A$24:$A$26,1)))) -> 40 | M2: =IF(G2="Prospecting",1,INDEX(Parâmetros!$C$32:$C$35,MATCH(J2,Parâmetros!$A$32:$A$35,1))) -> 1 | N2: =ROUND((K2+L2)*M2,0) -> 100 | O2: =IF(AND(G2="Engaging",J2>Parâmetros!$B$6),"Sim","Não") -> Não | P2: =IF(O2="Sim","R",IF(N2>=Parâmetros!$B$39,"A",IF(N2>=Parâmetros!$B$40,"B",IF(N2>=Parâmetros!$B$41,"C","D")))) -> A | Q2: =IF(F2="","Completar cadastro","") | R2: =INDEX(Parâmetros!$D$39:$D$43,MATCH(P2,Parâmetros!$A$39:$A$43,0)) -> Prioridade máxima: próximo passo em até 48h
A3: 5378T3K3 | B3: Markita Hansen | C3: Celia Rouche | D3: West | E3: GTX Plus Pro | G3: Engaging | H3: 42962 | I3: =INDEX(Parâmetros!$C$13:$C$19,MATCH(E3,Parâmetros!$A$13:$A$19,0)) -> 5482 | J3: =IF(H3="","",Parâmetros!$B$5-H3) -> 138 | K3: =INDEX(Parâmetros!$D$13:$D$19,MATCH(E3,Parâmetros!$A$13:$A$19,0)) -> 45 | L3: =IF(G3="Prospecting",Parâmetros!$B$9,IF(J3>Parâmetros!$B$6,0,INDEX(Parâmetros!$C$24:$C$26,MATCH(J3,Parâmetros!$A$24:$A$26,1)))) -> 40 | M3: =IF(G3="Prospecting",1,INDEX(Parâmetros!$C$32:$C$35,MATCH(J3,Parâmetros!$A$32:$A$35,1))) -> 1 | N3: =ROUND((K3+L3)*M3,0) -> 85 | O3: =IF(AND(G3="Engaging",J3>Parâmetros!$B$6),"Sim","Não") -> Não | P3: =IF(O3="Sim","R",IF(N3>=Parâmetros!$B$39,"A",IF(N3>=Parâmetros!$B$40,"B",IF(N3>=Parâmetros!$B$41,"C","D")))) -> A | Q3: =IF(F3="","Completar cadastro","") -> Completar cadastro | R3: =INDEX(Parâmetros!$D$39:$D$43,MATCH(P3,Parâmetros!$A$39:$A$43,0)) -> Prioridade máxima: próximo passo em até 48h
A4: HF1GSBT4 | B4: Daniell Hammack | C4: Rocco Neubert | D4: East | E4: GTX Plus Pro | G4: Engaging | H4: 42971 | I4: =INDEX(Parâmetros!$C$13:$C$19,MATCH(E4,Parâmetros!$A$13:$A$19,0)) -> 5482 | J4: =IF(H4="","",Parâmetros!$B$5-H4) -> 129 | K4: =INDEX(Parâmetros!$D$13:$D$19,MATCH(E4,Parâmetros!$A$13:$A$19,0)) -> 45 | L4: =IF(G4="Prospecting",Parâmetros!$B$9,IF(J4>Parâmetros!$B$6,0,INDEX(Parâmetros!$C$24:$C$26,MATCH(J4,Parâmetros!$A$24:$A$26,1)))) -> 40 | M4: =IF(G4="Prospecting",1,INDEX(Parâmetros!$C$32:$C$35,MATCH(J4,Parâmetros!$A$32:$A$35,1))) -> 1 | N4: =ROUND((K4+L4)*M4,0) -> 85 | O4: =IF(AND(G4="Engaging",J4>Parâmetros!$B$6),"Sim","Não") -> Não | P4: =IF(O4="Sim","R",IF(N4>=Parâmetros!$B$39,"A",IF(N4>=Parâmetros!$B$40,"B",IF(N4>=Parâmetros!$B$41,"C","D")))) -> A | Q4: =IF(F4="","Completar cadastro","") -> Completar cadastro | R4: =INDEX(Parâmetros!$D$39:$D$43,MATCH(P4,Parâmetros!$A$39:$A$43,0)) -> Prioridade máxima: próximo passo em até 48h
A5: Y0M8X7BV | B5: Corliss Cosme | C5: Cara Losch | D5: East | E5: GTX Plus Pro | G5: Engaging | H5: 42972 | I5: =INDEX(Parâmetros!$C$13:$C$19,MATCH(E5,Parâmetros!$A$13:$A$19,0)) -> 5482 | J5: =IF(H5="","",Parâmetros!$B$5-H5) -> 128 | K5: =INDEX(Parâmetros!$D$13:$D$19,MATCH(E5,Parâmetros!$A$13:$A$19,0)) -> 45 | L5: =IF(G5="Prospecting",Parâmetros!$B$9,IF(J5>Parâmetros!$B$6,0,INDEX(Parâmetros!$C$24:$C$26,MATCH(J5,Parâmetros!$A$24:$A$26,1)))) -> 40 | M5: =IF(G5="Prospecting",1,INDEX(Parâmetros!$C$32:$C$35,MATCH(J5,Parâmetros!$A$32:$A$35,1))) -> 1 | N5: =ROUND((K5+L5)*M5,0) -> 85 | O5: =IF(AND(G5="Engaging",J5>Parâmetros!$B$6),"Sim","Não") -> Não | P5: =IF(O5="Sim","R",IF(N5>=Parâmetros!$B$39,"A",IF(N5>=Parâmetros!$B$40,"B",IF(N5>=Parâmetros!$B$41,"C","D")))) -> A | Q5: =IF(F5="","Completar cadastro","") -> Completar cadastro | R5: =INDEX(Parâmetros!$D$39:$D$43,MATCH(P5,Parâmetros!$A$39:$A$43,0)) -> Prioridade máxima: próximo passo em até 48h
A6: 059K86LU | B6: Kami Bicknell | C6: Summer Sewald | D6: West | E6: GTX Plus Pro | F6: Labdrill | G6: Engaging | H6: 42973 | I6: =INDEX(Parâmetros!$C$13:$C$19,MATCH(E6,Parâmetros!$A$13:$A$19,0)) -> 5482 | J6: =IF(H6="","",Parâmetros!$B$5-H6) -> 127 | K6: =INDEX(Parâmetros!$D$13:$D$19,MATCH(E6,Parâmetros!$A$13:$A$19,0)) -> 45 | L6: =IF(G6="Prospecting",Parâmetros!$B$9,IF(J6>Parâmetros!$B$6,0,INDEX(Parâmetros!$C$24:$C$26,MATCH(J6,Parâmetros!$A$24:$A$26,1)))) -> 40 | M6: =IF(G6="Prospecting",1,INDEX(Parâmetros!$C$32:$C$35,MATCH(J6,Parâmetros!$A$32:$A$35,1))) -> 1 | N6: =ROUND((K6+L6)*M6,0) -> 85 | O6: =IF(AND(G6="Engaging",J6>Parâmetros!$B$6),"Sim","Não") -> Não | P6: =IF(O6="Sim","R",IF(N6>=Parâmetros!$B$39,"A",IF(N6>=Parâmetros!$B$40,"B",IF(N6>=Parâmetros!$B$41,"C","D")))) -> A | Q6: =IF(F6="","Completar cadastro","") | R6: =INDEX(Parâmetros!$D$39:$D$43,MATCH(P6,Parâmetros!$A$39:$A$43,0)) -> Prioridade máxima: próximo passo em até 48h
A7: WZN26QZQ | B7: Corliss Cosme | C7: Cara Losch | D7: East | E7: GTX Plus Pro | F7: Lexiqvolax | G7: Engaging | H7: 42974 | I7: =INDEX(Parâmetros!$C$13:$C$19,MATCH(E7,Parâmetros!$A$13:$A$19,0)) -> 5482 | J7: =IF(H7="","",Parâmetros!$B$5-H7) -> 126 | K7: =INDEX(Parâmetros!$D$13:$D$19,MATCH(E7,Parâmetros!$A$13:$A$19,0)) -> 45 | L7: =IF(G7="Prospecting",Parâmetros!$B$9,IF(J7>Parâmetros!$B$6,0,INDEX(Parâmetros!$C$24:$C$26,MATCH(J7,Parâmetros!$A$24:$A$26,1)))) -> 40 | M7: =IF(G7="Prospecting",1,INDEX(Parâmetros!$C$32:$C$35,MATCH(J7,Parâmetros!$A$32:$A$35,1))) -> 1 | N7: =ROUND((K7+L7)*M7,0) -> 85 | O7: =IF(AND(G7="Engaging",J7>Parâmetros!$B$6),"Sim","Não") -> Não | P7: =IF(O7="Sim","R",IF(N7>=Parâmetros!$B$39,"A",IF(N7>=Parâmetros!$B$40,"B",IF(N7>=Parâmetros!$B$41,"C","D")))) -> A | Q7: =IF(F7="","Completar cadastro","") | R7: =INDEX(Parâmetros!$D$39:$D$43,MATCH(P7,Parâmetros!$A$39:$A$43,0)) -> Prioridade máxima: próximo passo em até 48h
A8: A5SCVK7E | B8: Corliss Cosme | C8: Cara Losch | D8: East | E8: GTX Plus Pro | F8: Goodsilron | G8: Engaging | H8: 42979 | I8: =INDEX(Parâmetros!$C$13:$C$19,MATCH(E8,Parâmetros!$A$13:$A$19,0)) -> 5482 | J8: =IF(H8="","",Parâmetros!$B$5-H8) -> 121 | K8: =INDEX(Parâmetros!$D$13:$D$19,MATCH(E8,Parâmetros!$A$13:$A$19,0)) -> 45 | L8: =IF(G8="Prospecting",Parâmetros!$B$9,IF(J8>Parâmetros!$B$6,0,INDEX(Parâmetros!$C$24:$C$26,MATCH(J8,Parâmetros!$A$24:$A$26,1)))) -> 40 | M8: =IF(G8="Prospecting",1,INDEX(Parâmetros!$C$32:$C$35,MATCH(J8,Parâmetros!$A$32:$A$35,1))) -> 1 | N8: =ROUND((K8+L8)*M8,0) -> 85 | O8: =IF(AND(G8="Engaging",J8>Parâmetros!$B$6),"Sim","Não") -> Não | P8: =IF(O8="Sim","R",IF(N8>=Parâmetros!$B$39,"A",IF(N8>=Parâmetros!$B$40,"B",IF(N8>=Parâmetros!$B$41,"C","D")))) -> A | Q8: =IF(F8="","Completar cadastro","") | R8: =INDEX(Parâmetros!$D$39:$D$43,MATCH(P8,Parâmetros!$A$39:$A$43,0)) -> Prioridade máxima: próximo passo em até 48h
A9: KAGK2GQJ | B9: James Ascencio | C9: Summer Sewald | D9: West | E9: GTX Plus Pro | G9: Engaging | H9: 42979 | I9: =INDEX(Parâmetros!$C$13:$C$19,MATCH(E9,Parâmetros!$A$13:$A$19,0)) -> 5482 | J9: =IF(H9="","",Parâmetros!$B$5-H9) -> 121 | K9: =INDEX(Parâmetros!$D$13:$D$19,MATCH(E9,Parâmetros!$A$13:$A$19,0)) -> 45 | L9: =IF(G9="Prospecting",Parâmetros!$B$9,IF(J9>Parâmetros!$B$6,0,INDEX(Parâmetros!$C$24:$C$26,MATCH(J9,Parâmetros!$A$24:$A$26,1)))) -> 40 | M9: =IF(G9="Prospecting",1,INDEX(Parâmetros!$C$32:$C$35,MATCH(J9,Parâmetros!$A$32:$A$35,1))) -> 1 | N9: =ROUND((K9+L9)*M9,0) -> 85 | O9: =IF(AND(G9="Engaging",J9>Parâmetros!$B$6),"Sim","Não") -> Não | P9: =IF(O9="Sim","R",IF(N9>=Parâmetros!$B$39,"A",IF(N9>=Parâmetros!$B$40,"B",IF(N9>=Parâmetros!$B$41,"C","D")))) -> A | Q9: =IF(F9="","Completar cadastro","") -> Completar cadastro | R9: =INDEX(Parâmetros!$D$39:$D$43,MATCH(P9,Parâmetros!$A$39:$A$43,0)) -> Prioridade máxima: próximo passo em até 48h
A10: 6OD1J7MW | B10: Elease Gluck | C10: Celia Rouche | D10: West | E10: GTX Plus Pro | F10: Plexzap | G10: Engaging | H10: 42980 | I10: =INDEX(Parâmetros!$C$13:$C$19,MATCH(E10,Parâmetros!$A$13:$A$19,0)) -> 5482 | J10: =IF(H10="","",Parâmetros!$B$5-H10) -> 120 | K10: =INDEX(Parâmetros!$D$13:$D$19,MATCH(E10,Parâmetros!$A$13:$A$19,0)) -> 45 | L10: =IF(G10="Prospecting",Parâmetros!$B$9,IF(J10>Parâmetros!$B$6,0,INDEX(Parâmetros!$C$24:$C$26,MATCH(J10,Parâmetros!$A$24:$A$26,1)))) -> 40 | M10: =IF(G10="Prospecting",1,INDEX(Parâmetros!$C$32:$C$35,MATCH(J10,Parâmetros!$A$32:$A$35,1))) -> 1 | N10: =ROUND((K10+L10)*M10,0) -> 85 | O10: =IF(AND(G10="Engaging",J10>Parâmetros!$B$6),"Sim","Não") -> Não | P10: =IF(O10="Sim","R",IF(N10>=Parâmetros!$B$39,"A",IF(N10>=Parâmetros!$B$40,"B",IF(N10>=Parâmetros!$B$41,"C","D")))) -> A | Q10: =IF(F10="","Completar cadastro","") | R10: =INDEX(Parâmetros!$D$39:$D$43,MATCH(P10,Parâmetros!$A$39:$A$43,0)) -> Prioridade máxima: próximo passo em até 48h
A11: J0G6ZLYZ | B11: Zane Levy | C11: Summer Sewald | D11: West | E11: GTX Plus Pro | G11: Engaging | H11: 42980 | I11: =INDEX(Parâmetros!$C$13:$C$19,MATCH(E11,Parâmetros!$A$13:$A$19,0)) -> 5482 | J11: =IF(H11="","",Parâmetros!$B$5-H11) -> 120 | K11: =INDEX(Parâmetros!$D$13:$D$19,MATCH(E11,Parâmetros!$A$13:$A$19,0)) -> 45 | L11: =IF(G11="Prospecting",Parâmetros!$B$9,IF(J11>Parâmetros!$B$6,0,INDEX(Parâmetros!$C$24:$C$26,MATCH(J11,Parâmetros!$A$24:$A$26,1)))) -> 40 | M11: =IF(G11="Prospecting",1,INDEX(Parâmetros!$C$32:$C$35,MATCH(J11,Parâmetros!$A$32:$A$35,1))) -> 1 | N11: =ROUND((K11+L11)*M11,0) -> 85 | O11: =IF(AND(G11="Engaging",J11>Parâmetros!$B$6),"Sim","Não") -> Não | P11: =IF(O11="Sim","R",IF(N11>=Parâmetros!$B$39,"A",IF(N11>=Parâmetros!$B$40,"B",IF(N11>=Parâmetros!$B$41,"C","D")))) -> A | Q11: =IF(F11="","Completar cadastro","") -> Completar cadastro | R11: =INDEX(Parâmetros!$D$39:$D$43,MATCH(P11,Parâmetros!$A$39:$A$43,0)) -> Prioridade máxima: próximo passo em até 48h
A12: H8XH5MFQ | B12: Kary Hendrixson | C12: Summer Sewald | D12: West | E12: GTX Plus Pro | G12: Engaging | H12: 42981 | I12: =INDEX(Parâmetros!$C$13:$C$19,MATCH(E12,Parâmetros!$A$13:$A$19,0)) -> 5482 | J12: =IF(H12="","",Parâmetros!$B$5-H12) -> 119 | K12: =INDEX(Parâmetros!$D$13:$D$19,MATCH(E12,Parâmetros!$A$13:$A$19,0)) -> 45 | L12: =IF(G12="Prospecting",Parâmetros!$B$9,IF(J12>Parâmetros!$B$6,0,INDEX(Parâmetros!$C$24:$C$26,MATCH(J12,Parâmetros!$A$24:$A$26,1)))) -> 40 | M12: =IF(G12="Prospecting",1,INDEX(Parâmetros!$C$32:$C$35,MATCH(J12,Parâmetros!$A$32:$A$35,1))) -> 1 | N12: =ROUND((K12+L12)*M12,0) -> 85 | O12: =IF(AND(G12="Engaging",J12>Parâmetros!$B$6),"Sim","Não") -> Não | P12: =IF(O12="Sim","R",IF(N12>=Parâmetros!$B$39,"A",IF(N12>=Parâmetros!$B$40,"B",IF(N12>=Parâmetros!$B$41,"C","D")))) -> A | Q12: =IF(F12="","Completar cadastro","") -> Completar cadastro | R12: =INDEX(Parâmetros!$D$39:$D$43,MATCH(P12,Parâmetros!$A$39:$A$43,0)) -> Prioridade máxima: próximo passo em até 48h
A13: 7GDSUY9K | B13: Hayden Neloms | C13: Celia Rouche | D13: West | E13: GTX Plus Pro | F13: Konmatfix | G13: Engaging | H13: 42983 | I13: =INDEX(Parâmetros!$C$13:$C$19,MATCH(E13,Parâmetros!$A$13:$A$19,0)) -> 5482 | J13: =IF(H13="","",Parâmetros!$B$5-H13) -> 117 | K13: =INDEX(Parâmetros!$D$13:$D$19,MATCH(E13,Parâmetros!$A$13:$A$19,0)) -> 45 | L13: =IF(G13="Prospecting",Parâmetros!$B$9,IF(J13>Parâmetros!$B$6,0,INDEX(Parâmetros!$C$24:$C$26,MATCH(J13,Parâmetros!$A$24:$A$26,1)))) -> 40 | M13: =IF(G13="Prospecting",1,INDEX(Parâmetros!$C$32:$C$35,MATCH(J13,Parâmetros!$A$32:$A$35,1))) -> 1 | N13: =ROUND((K13+L13)*M13,0) -> 85 | O13: =IF(AND(G13="Engaging",J13>Parâmetros!$B$6),"Sim","Não") -> Não | P13: =IF(O13="Sim","R",IF(N13>=Parâmetros!$B$39,"A",IF(N13>=Parâmetros!$B$40,"B",IF(N13>=Parâmetros!$B$41,"C","D")))) -> A | Q13: =IF(F13="","Completar cadastro","") | R13: =INDEX(Parâmetros!$D$39:$D$43,MATCH(P13,Parâmetros!$A$39:$A$43,0)) -> Prioridade máxima: próximo passo em até 48h
A14: 77IBMLTB | B14: James Ascencio | C14: Summer Sewald | D14: West | E14: GTX Plus Pro | G14: Engaging | H14: 42989 | I14: =INDEX(Parâmetros!$C$13:$C$19,MATCH(E14,Parâmetros!$A$13:$A$19,0)) -> 5482 | J14: =IF(H14="","",Parâmetros!$B$5-H14) -> 111 | K14: =INDEX(Parâmetros!$D$13:$D$19,MATCH(E14,Parâmetros!$A$13:$A$19,0)) -> 45 | L14: =IF(G14="Prospecting",Parâmetros!$B$9,IF(J14>Parâmetros!$B$6,0,INDEX(Parâmetros!$C$24:$C$26,MATCH(J14,Parâmetros!$A$24:$A$26,1)))) -> 40 | M14: =IF(G14="Prospecting",1,INDEX(Parâmetros!$C$32:$C$35,MATCH(J14,Parâmetros!$A$32:$A$35,1))) -> 1 | N14: =ROUND((K14+L14)*M14,0) -> 85 | O14: =IF(AND(G14="Engaging",J14>Parâmetros!$B$6),"Sim","Não") -> Não | P14: =IF(O14="Sim","R",IF(N14>=Parâmetros!$B$39,"A",IF(N14>=Parâmetros!$B$40,"B",IF(N14>=Parâmetros!$B$41,"C","D")))) -> A | Q14: =IF(F14="","Completar cadastro","") -> Completar cadastro | R14: =INDEX(Parâmetros!$D$39:$D$43,MATCH(P14,Parâmetros!$A$39:$A$43,0)) -> Prioridade máxima: próximo passo em até 48h
A15: VRWH3YJV | B15: Maureen Marcano | C15: Summer Sewald | D15: West | E15: GTX Plus Pro | G15: Engaging | H15: 42992 | I15: =INDEX(Parâmetros!$C$13:$C$19,MATCH(E15,Parâmetros!$A$13:$A$19,0)) -> 5482 | J15: =IF(H15="","",Parâmetros!$B$5-H15) -> 108 | K15: =INDEX(Parâmetros!$D$13:$D$19,MATCH(E15,Parâmetros!$A$13:$A$19,0)) -> 45 | L15: =IF(G15="Prospecting",Parâmetros!$B$9,IF(J15>Parâmetros!$B$6,0,INDEX(Parâmetros!$C$24:$C$26,MATCH(J15,Parâmetros!$A$24:$A$26,1)))) -> 40 | M15: =IF(G15="Prospecting",1,INDEX(Parâmetros!$C$32:$C$35,MATCH(J15,Parâmetros!$A$32:$A$35,1))) -> 1 | N15: =ROUND((K15+L15)*M15,0) -> 85 | O15: =IF(AND(G15="Engaging",J15>Parâmetros!$B$6),"Sim","Não") -> Não | P15: =IF(O15="Sim","R",IF(N15>=Parâmetros!$B$39,"A",IF(N15>=Parâmetros!$B$40,"B",IF(N15>=Parâmetros!$B$41,"C","D")))) -> A | Q15: =IF(F15="","Completar cadastro","") -> Completar cadastro | R15: =INDEX(Parâmetros!$D$39:$D$43,MATCH(P15,Parâmetros!$A$39:$A$43,0)) -> Prioridade máxima: próximo passo em até 48h
A16: R6Q5JOLX | B16: Cassey Cress | C16: Rocco Neubert | D16: East | E16: GTX Plus Pro | G16: Engaging | H16: 42994 | I16: =INDEX(Parâmetros!$C$13:$C$19,MATCH(E16,Parâmetros!$A$13:$A$19,0)) -> 5482 | J16: =IF(H16="","",Parâmetros!$B$5-H16) -> 106 | K16: =INDEX(Parâmetros!$D$13:$D$19,MATCH(E16,Parâmetros!$A$13:$A$19,0)) -> 45 | L16: =IF(G16="Prospecting",Parâmetros!$B$9,IF(J16>Parâmetros!$B$6,0,INDEX(Parâmetros!$C$24:$C$26,MATCH(J16,Parâmetros!$A$24:$A$26,1)))) -> 40 | M16: =IF(G16="Prospecting",1,INDEX(Parâmetros!$C$32:$C$35,MATCH(J16,Parâmetros!$A$32:$A$35,1))) -> 1 | N16: =ROUND((K16+L16)*M16,0) -> 85 | O16: =IF(AND(G16="Engaging",J16>Parâmetros!$B$6),"Sim","Não") -> Não | P16: =IF(O16="Sim","R",IF(N16>=Parâmetros!$B$39,"A",IF(N16>=Parâmetros!$B$40,"B",IF(N16>=Parâmetros!$B$41,"C","D")))) -> A | Q16: =IF(F16="","Completar cadastro","") -> Completar cadastro | R16: =INDEX(Parâmetros!$D$39:$D$43,MATCH(P16,Parâmetros!$A$39:$A$43,0)) -> Prioridade máxima: próximo passo em até 48h
A17: DY8DMZZ9 | B17: Vicki Laflamme | C17: Celia Rouche | D17: West | E17: GTX Plus Pro | G17: Engaging | H17: 42994 | I17: =INDEX(Parâmetros!$C$13:$C$19,MATCH(E17,Parâmetros!$A$13:$A$19,0)) -> 5482 | J17: =IF(H17="","",Parâmetros!$B$5-H17) -> 106 | K17: =INDEX(Parâmetros!$D$13:$D$19,MATCH(E17,Parâmetros!$A$13:$A$19,0)) -> 45 | L17: =IF(G17="Prospecting",Parâmetros!$B$9,IF(J17>Parâmetros!$B$6,0,INDEX(Parâmetros!$C$24:$C$26,MATCH(J17,Parâmetros!$A$24:$A$26,1)))) -> 40 | M17: =IF(G17="Prospecting",1,INDEX(Parâmetros!$C$32:$C$35,MATCH(J17,Parâmetros!$A$32:$A$35,1))) -> 1 | N17: =ROUND((K17+L17)*M17,0) -> 85 | O17: =IF(AND(G17="Engaging",J17>Parâmetros!$B$6),"Sim","Não") -> Não | P17: =IF(O17="Sim","R",IF(N17>=Parâmetros!$B$39,"A",IF(N17>=Parâmetros!$B$40,"B",IF(N17>=Parâmetros!$B$41,"C","D")))) -> A | Q17: =IF(F17="","Completar cadastro","") -> Completar cadastro | R17: =INDEX(Parâmetros!$D$39:$D$43,MATCH(P17,Parâmetros!$A$39:$A$43,0)) -> Prioridade máxima: próximo passo em até 48h
A18: 01XZ9CRY | B18: Zane Levy | C18: Summer Sewald | D18: West | E18: GTX Plus Pro | F18: Initech | G18: Engaging | H18: 42996 | I18: =INDEX(Parâmetros!$C$13:$C$19,MATCH(E18,Parâmetros!$A$13:$A$19,0)) -> 5482 | J18: =IF(H18="","",Parâmetros!$B$5-H18) -> 104 | K18: =INDEX(Parâmetros!$D$13:$D$19,MATCH(E18,Parâmetros!$A$13:$A$19,0)) -> 45 | L18: =IF(G18="Prospecting",Parâmetros!$B$9,IF(J18>Parâmetros!$B$6,0,INDEX(Parâmetros!$C$24:$C$26,MATCH(J18,Parâmetros!$A$24:$A$26,1)))) -> 40 | M18: =IF(G18="Prospecting",1,INDEX(Parâmetros!$C$32:$C$35,MATCH(J18,Parâmetros!$A$32:$A$35,1))) -> 1 | N18: =ROUND((K18+L18)*M18,0) -> 85 | O18: =IF(AND(G18="Engaging",J18>Parâmetros!$B$6),"Sim","Não") -> Não | P18: =IF(O18="Sim","R",IF(N18>=Parâmetros!$B$39,"A",IF(N18>=Parâmetros!$B$40,"B",IF(N18>=Parâmetros!$B$41,"C","D")))) -> A | Q18: =IF(F18="","Completar cadastro","") | R18: =INDEX(Parâmetros!$D$39:$D$43,MATCH(P18,Parâmetros!$A$39:$A$43,0)) -> Prioridade máxima: próximo passo em até 48h
A19: A7OVC1WK | B19: Corliss Cosme | C19: Cara Losch | D19: East | E19: GTX Plus Pro | G19: Engaging | H19: 42997 | I19: =INDEX(Parâmetros!$C$13:$C$19,MATCH(E19,Parâmetros!$A$13:$A$19,0)) -> 5482 | J19: =IF(H19="","",Parâmetros!$B$5-H19) -> 103 | K19: =INDEX(Parâmetros!$D$13:$D$19,MATCH(E19,Parâmetros!$A$13:$A$19,0)) -> 45 | L19: =IF(G19="Prospecting",Parâmetros!$B$9,IF(J19>Parâmetros!$B$6,0,INDEX(Parâmetros!$C$24:$C$26,MATCH(J19,Parâmetros!$A$24:$A$26,1)))) -> 40 | M19: =IF(G19="Prospecting",1,INDEX(Parâmetros!$C$32:$C$35,MATCH(J19,Parâmetros!$A$32:$A$35,1))) -> 1 | N19: =ROUND((K19+L19)*M19,0) -> 85 | O19: =IF(AND(G19="Engaging",J19>Parâmetros!$B$6),"Sim","Não") -> Não | P19: =IF(O19="Sim","R",IF(N19>=Parâmetros!$B$39,"A",IF(N19>=Parâmetros!$B$40,"B",IF(N19>=Parâmetros!$B$41,"C","D")))) -> A | Q19: =IF(F19="","Completar cadastro","") -> Completar cadastro | R19: =INDEX(Parâmetros!$D$39:$D$43,MATCH(P19,Parâmetros!$A$39:$A$43,0)) -> Prioridade máxima: próximo passo em até 48h
A20: NRK892VX | B20: Elease Gluck | C20: Celia Rouche | D20: West | E20: GTX Plus Pro | G20: Engaging | H20: 42998 | I20: =INDEX(Parâmetros!$C$13:$C$19,MATCH(E20,Parâmetros!$A$13:$A$19,0)) -> 5482 | J20: =IF(H20="","",Parâmetros!$B$5-H20) -> 102 | K20: =INDEX(Parâmetros!$D$13:$D$19,MATCH(E20,Parâmetros!$A$13:$A$19,0)) -> 45 | L20: =IF(G20="Prospecting",Parâmetros!$B$9,IF(J20>Parâmetros!$B$6,0,INDEX(Parâmetros!$C$24:$C$26,MATCH(J20,Parâmetros!$A$24:$A$26,1)))) -> 40 | M20: =IF(G20="Prospecting",1,INDEX(Parâmetros!$C$32:$C$35,MATCH(J20,Parâmetros!$A$32:$A$35,1))) -> 1 | N20: =ROUND((K20+L20)*M20,0) -> 85 | O20: =IF(AND(G20="Engaging",J20>Parâmetros!$B$6),"Sim","Não") -> Não | P20: =IF(O20="Sim","R",IF(N20>=Parâmetros!$B$39,"A",IF(N20>=Parâmetros!$B$40,"B",IF(N20>=Parâmetros!$B$41,"C","D")))) -> A | Q20: =IF(F20="","Completar cadastro","") -> Completar cadastro | R20: =INDEX(Parâmetros!$D$39:$D$43,MATCH(P20,Parâmetros!$A$39:$A$43,0)) -> Prioridade máxima: próximo passo em até 48h
A21: LFI3BGEE | B21: Daniell Hammack | C21: Rocco Neubert | D21: East | E21: GTX Plus Pro | G21: Engaging | H21: 43000 | I21: =INDEX(Parâmetros!$C$13:$C$19,MATCH(E21,Parâmetros!$A$13:$A$19,0)) -> 5482 | J21: =IF(H21="","",Parâmetros!$B$5-H21) -> 100 | K21: =INDEX(Parâmetros!$D$13:$D$19,MATCH(E21,Parâmetros!$A$13:$A$19,0)) -> 45 | L21: =IF(G21="Prospecting",Parâmetros!$B$9,IF(J21>Parâmetros!$B$6,0,INDEX(Parâmetros!$C$24:$C$26,MATCH(J21,Parâmetros!$A$24:$A$26,1)))) -> 40 | M21: =IF(G21="Prospecting",1,INDEX(Parâmetros!$C$32:$C$35,MATCH(J21,Parâmetros!$A$32:$A$35,1))) -> 1 | N21: =ROUND((K21+L21)*M21,0) -> 85 | O21: =IF(AND(G21="Engaging",J21>Parâmetros!$B$6),"Sim","Não") -> Não | P21: =IF(O21="Sim","R",IF(N21>=Parâmetros!$B$39,"A",IF(N21>=Parâmetros!$B$40,"B",IF(N21>=Parâmetros!$B$41,"C","D")))) -> A | Q21: =IF(F21="","Completar cadastro","") -> Completar cadastro | R21: =INDEX(Parâmetros!$D$39:$D$43,MATCH(P21,Parâmetros!$A$39:$A$43,0)) -> Prioridade máxima: próximo passo em até 48h
A22: 9JTFD4FZ | B22: Wilburn Farren | C22: Cara Losch | D22: East | E22: GTX Plus Pro | G22: Engaging | H22: 43006 | I22: =INDEX(Parâmetros!$C$13:$C$19,MATCH(E22,Parâmetros!$A$13:$A$19,0)) -> 5482 | J22: =IF(H22="","",Parâmetros!$B$5-H22) -> 94 | K22: =INDEX(Parâmetros!$D$13:$D$19,MATCH(E22,Parâmetros!$A$13:$A$19,0)) -> 45 | L22: =IF(G22="Prospecting",Parâmetros!$B$9,IF(J22>Parâmetros!$B$6,0,INDEX(Parâmetros!$C$24:$C$26,MATCH(J22,Parâmetros!$A$24:$A$26,1)))) -> 40 | M22: =IF(G22="Prospecting",1,INDEX(Parâmetros!$C$32:$C$35,MATCH(J22,Parâmetros!$A$32:$A$35,1))) -> 1 | N22: =ROUND((K22+L22)*M22,0) -> 85 | O22: =IF(AND(G22="Engaging",J22>Parâmetros!$B$6),"Sim","Não") -> Não | P22: =IF(O22="Sim","R",IF(N22>=Parâmetros!$B$39,"A",IF(N22>=Parâmetros!$B$40,"B",IF(N22>=Parâmetros!$B$41,"C","D")))) -> A | Q22: =IF(F22="","Completar cadastro","") -> Completar cadastro | R22: =INDEX(Parâmetros!$D$39:$D$43,MATCH(P22,Parâmetros!$A$39:$A$43,0)) -> Prioridade máxima: próximo passo em até 48h
A23: NX28C8EI | B23: James Ascencio | C23: Summer Sewald | D23: West | E23: GTX Plus Pro | G23: Engaging | H23: 43008 | I23: =INDEX(Parâmetros!$C$13:$C$19,MATCH(E23,Parâmetros!$A$13:$A$19,0)) -> 5482 | J23: =IF(H23="","",Parâmetros!$B$5-H23) -> 92 | K23: =INDEX(Parâmetros!$D$13:$D$19,MATCH(E23,Parâmetros!$A$13:$A$19,0)) -> 45 | L23: =IF(G23="Prospecting",Parâmetros!$B$9,IF(J23>Parâmetros!$B$6,0,INDEX(Parâmetros!$C$24:$C$26,MATCH(J23,Parâmetros!$A$24:$A$26,1)))) -> 40 | M23: =IF(G23="Prospecting",1,INDEX(Parâmetros!$C$32:$C$35,MATCH(J23,Parâmetros!$A$32:$A$35,1))) -> 1 | N23: =ROUND((K23+L23)*M23,0) -> 85 | O23: =IF(AND(G23="Engaging",J23>Parâmetros!$B$6),"Sim","Não") -> Não | P23: =IF(O23="Sim","R",IF(N23>=Parâmetros!$B$39,"A",IF(N23>=Parâmetros!$B$40,"B",IF(N23>=Parâmetros!$B$41,"C","D")))) -> A | Q23: =IF(F23="","Completar cadastro","") -> Completar cadastro | R23: =INDEX(Parâmetros!$D$39:$D$43,MATCH(P23,Parâmetros!$A$39:$A$43,0)) -> Prioridade máxima: próximo passo em até 48h
A24: NMLTE4CS | B24: Maureen Marcano | C24: Summer Sewald | D24: West | E24: GTX Plus Pro | G24: Engaging | H24: 43008 | I24: =INDEX(Parâmetros!$C$13:$C$19,MATCH(E24,Parâmetros!$A$13:$A$19,0)) -> 5482 | J24: =IF(H24="","",Parâmetros!$B$5-H24) -> 92 | K24: =INDEX(Parâmetros!$D$13:$D$19,MATCH(E24,Parâmetros!$A$13:$A$19,0)) -> 45 | L24: =IF(G24="Prospecting",Parâmetros!$B$9,IF(J24>Parâmetros!$B$6,0,INDEX(Parâmetros!$C$24:$C$26,MATCH(J24,Parâmetros!$A$24:$A$26,1)))) -> 40 | M24: =IF(G24="Prospecting",1,INDEX(Parâmetros!$C$32:$C$35,MATCH(J24,Parâmetros!$A$32:$A$35,1))) -> 1 | N24: =ROUND((K24+L24)*M24,0) -> 85 | O24: =IF(AND(G24="Engaging",J24>Parâmetros!$B$6),"Sim","Não") -> Não | P24: =IF(O24="Sim","R",IF(N24>=Parâmetros!$B$39,"A",IF(N24>=Parâmetros!$B$40,"B",IF(N24>=Parâmetros!$B$41,"C","D")))) -> A | Q24: =IF(F24="","Completar cadastro","") -> Completar cadastro | R24: =INDEX(Parâmetros!$D$39:$D$43,MATCH(P24,Parâmetros!$A$39:$A$43,0)) -> Prioridade máxima: próximo passo em até 48h
A25: 4SOUOUKH | B25: Vicki Laflamme | C25: Celia Rouche | D25: West | E25: GTX Plus Pro | F25: Treequote | G25: Engaging | H25: 43008 | I25: =INDEX(Parâmetros!$C$13:$C$19,MATCH(E25,Parâmetros!$A$13:$A$19,0)) -> 5482 | J25: =IF(H25="","",Parâmetros!$B$5-H25) -> 92 | K25: =INDEX(Parâmetros!$D$13:$D$19,MATCH(E25,Parâmetros!$A$13:$A$19,0)) -> 45 | L25: =IF(G25="Prospecting",Parâmetros!$B$9,IF(J25>Parâmetros!$B$6,0,INDEX(Parâmetros!$C$24:$C$26,MATCH(J25,Parâmetros!$A$24:$A$26,1)))) -> 40 | M25: =IF(G25="Prospecting",1,INDEX(Parâmetros!$C$32:$C$35,MATCH(J25,Parâmetros!$A$32:$A$35,1))) -> 1 | N25: =ROUND((K25+L25)*M25,0) -> 85 | O25: =IF(AND(G25="Engaging",J25>Parâmetros!$B$6),"Sim","Não") -> Não | P25: =IF(O25="Sim","R",IF(N25>=Parâmetros!$B$39,"A",IF(N25>=Parâmetros!$B$40,"B",IF(N25>=Parâmetros!$B$41,"C","D")))) -> A | Q25: =IF(F25="","Completar cadastro","") | R25: =INDEX(Parâmetros!$D$39:$D$43,MATCH(P25,Parâmetros!$A$39:$A$43,0)) -> Prioridade máxima: próximo passo em até 48h
A26: QNB3SCN9 | B26: Wilburn Farren | C26: Cara Losch | D26: East | E26: GTX Plus Pro | G26: Engaging | H26: 43009 | I26: =INDEX(Parâmetros!$C$13:$C$19,MATCH(E26,Parâmetros!$A$13:$A$19,0)) -> 5482 | J26: =IF(H26="","",Parâmetros!$B$5-H26) -> 91 | K26: =INDEX(Parâmetros!$D$13:$D$19,MATCH(E26,Parâmetros!$A$13:$A$19,0)) -> 45 | L26: =IF(G26="Prospecting",Parâmetros!$B$9,IF(J26>Parâmetros!$B$6,0,INDEX(Parâmetros!$C$24:$C$26,MATCH(J26,Parâmetros!$A$24:$A$26,1)))) -> 40 | M26: =IF(G26="Prospecting",1,INDEX(Parâmetros!$C$32:$C$35,MATCH(J26,Parâmetros!$A$32:$A$35,1))) -> 1 | N26: =ROUND((K26+L26)*M26,0) -> 85 | O26: =IF(AND(G26="Engaging",J26>Parâmetros!$B$6),"Sim","Não") -> Não | P26: =IF(O26="Sim","R",IF(N26>=Parâmetros!$B$39,"A",IF(N26>=Parâmetros!$B$40,"B",IF(N26>=Parâmetros!$B$41,"C","D")))) -> A | Q26: =IF(F26="","Completar cadastro","") -> Completar cadastro | R26: =INDEX(Parâmetros!$D$39:$D$43,MATCH(P26,Parâmetros!$A$39:$A$43,0)) -> Prioridade máxima: próximo passo em até 48h
A27: PYQ3VX08 | B27: Niesha Huffines | C27: Melvin Marxen | D27: Central | E27: GTX Pro | G27: Engaging | H27: 42962 | I27: =INDEX(Parâmetros!$C$13:$C$19,MATCH(E27,Parâmetros!$A$13:$A$19,0)) -> 4821 | J27: =IF(H27="","",Parâmetros!$B$5-H27) -> 138 | K27: =INDEX(Parâmetros!$D$13:$D$19,MATCH(E27,Parâmetros!$A$13:$A$19,0)) -> 43 | L27: =IF(G27="Prospecting",Parâmetros!$B$9,IF(J27>Parâmetros!$B$6,0,INDEX(Parâmetros!$C$24:$C$26,MATCH(J27,Parâmetros!$A$24:$A$26,1)))) -> 40 | M27: =IF(G27="Prospecting",1,INDEX(Parâmetros!$C$32:$C$35,MATCH(J27,Parâmetros!$A$32:$A$35,1))) -> 1 | N27: =ROUND((K27+L27)*M27,0) -> 83 | O27: =IF(AND(G27="Engaging",J27>Parâmetros!$B$6),"Sim","Não") -> Não | P27: =IF(O27="Sim","R",IF(N27>=Parâmetros!$B$39,"A",IF(N27>=Parâmetros!$B$40,"B",IF(N27>=Parâmetros!$B$41,"C","D")))) -> A | Q27: =IF(F27="","Completar cadastro","") -> Completar cadastro | R27: =INDEX(Parâmetros!$D$39:$D$43,MATCH(P27,Parâmetros!$A$39:$A$43,0)) -> Prioridade máxima: próximo passo em até 48h
A28: 6SMB6SDY | B28: Vicki Laflamme | C28: Celia Rouche | D28: West | E28: GTX Pro | G28: Engaging | H28: 42962 | I28: =INDEX(Parâmetros!$C$13:$C$19,MATCH(E28,Parâmetros!$A$13:$A$19,0)) -> 4821 | J28: =IF(H28="","",Parâmetros!$B$5-H28) -> 138 | K28: =INDEX(Parâmetros!$D$13:$D$19,MATCH(E28,Parâmetros!$A$13:$A$19,0)) -> 43 | L28: =IF(G28="Prospecting",Parâmetros!$B$9,IF(J28>Parâmetros!$B$6,0,INDEX(Parâmetros!$C$24:$C$26,MATCH(J28,Parâmetros!$A$24:$A$26,1)))) -> 40 | M28: =IF(G28="Prospecting",1,INDEX(Parâmetros!$C$32:$C$35,MATCH(J28,Parâmetros!$A$32:$A$35,1))) -> 1 | N28: =ROUND((K28+L28)*M28,0) -> 83 | O28: =IF(AND(G28="Engaging",J28>Parâmetros!$B$6),"Sim","Não") -> Não | P28: =IF(O28="Sim","R",IF(N28>=Parâmetros!$B$39,"A",IF(N28>=Parâmetros!$B$40,"B",IF(N28>=Parâmetros!$B$41,"C","D")))) -> A | Q28: =IF(F28="","Completar cadastro","") -> Completar cadastro | R28: =INDEX(Parâmetros!$D$39:$D$43,MATCH(P28,Parâmetros!$A$39:$A$43,0)) -> Prioridade máxima: próximo passo em até 48h
A29: 041Q1IZL | B29: Zane Levy | C29: Summer Sewald | D29: West | E29: GTX Pro | F29: Green-Plus | G29: Engaging | H29: 42962 | I29: =INDEX(Parâmetros!$C$13:$C$19,MATCH(E29,Parâmetros!$A$13:$A$19,0)) -> 4821 | J29: =IF(H29="","",Parâmetros!$B$5-H29) -> 138 | K29: =INDEX(Parâmetros!$D$13:$D$19,MATCH(E29,Parâmetros!$A$13:$A$19,0)) -> 43 | L29: =IF(G29="Prospecting",Parâmetros!$B$9,IF(J29>Parâmetros!$B$6,0,INDEX(Parâmetros!$C$24:$C$26,MATCH(J29,Parâmetros!$A$24:$A$26,1)))) -> 40 | M29: =IF(G29="Prospecting",1,INDEX(Parâmetros!$C$32:$C$35,MATCH(J29,Parâmetros!$A$32:$A$35,1))) -> 1 | N29: =ROUND((K29+L29)*M29,0) -> 83 | O29: =IF(AND(G29="Engaging",J29>Parâmetros!$B$6),"Sim","Não") -> Não | P29: =IF(O29="Sim","R",IF(N29>=Parâmetros!$B$39,"A",IF(N29>=Parâmetros!$B$40,"B",IF(N29>=Parâmetros!$B$41,"C","D")))) -> A | Q29: =IF(F29="","Completar cadastro","") | R29: =INDEX(Parâmetros!$D$39:$D$43,MATCH(P29,Parâmetros!$A$39:$A$43,0)) -> Prioridade máxima: próximo passo em até 48h
A30: FKVC924F | B30: Daniell Hammack | C30: Rocco Neubert | D30: East | E30: GTX Pro | G30: Engaging | H30: 42964 | I30: =INDEX(Parâmetros!$C$13:$C$19,MATCH(E30,Parâmetros!$A$13:$A$19,0)) -> 4821 | J30: =IF(H30="","",Parâmetros!$B$5-H30) -> 136 | K30: =INDEX(Parâmetros!$D$13:$D$19,MATCH(E30,Parâmetros!$A$13:$A$19,0)) -> 43 | L30: =IF(G30="Prospecting",Parâmetros!$B$9,IF(J30>Parâmetros!$B$6,0,INDEX(Parâmetros!$C$24:$C$26,MATCH(J30,Parâmetros!$A$24:$A$26,1)))) -> 40 | M30: =IF(G30="Prospecting",1,INDEX(Parâmetros!$C$32:$C$35,MATCH(J30,Parâmetros!$A$32:$A$35,1))) -> 1 | N30: =ROUND((K30+L30)*M30,0) -> 83 | O30: =IF(AND(G30="Engaging",J30>Parâmetros!$B$6),"Sim","Não") -> Não | P30: =IF(O30="Sim","R",IF(N30>=Parâmetros!$B$39,"A",IF(N30>=Parâmetros!$B$40,"B",IF(N30>=Parâmetros!$B$41,"C","D")))) -> A | Q30: =IF(F30="","Completar cadastro","") -> Completar cadastro | R30: =INDEX(Parâmetros!$D$39:$D$43,MATCH(P30,Parâmetros!$A$39:$A$43,0)) -> Prioridade máxima: próximo passo em até 48h
A31: LXVCMY4C | B31: Daniell Hammack | C31: Rocco Neubert | D31: East | E31: GTX Pro | G31: Engaging | H31: 42964 | I31: =INDEX(Parâmetros!$C$13:$C$19,MATCH(E31,Parâmetros!$A$13:$A$19,0)) -> 4821 | J31: =IF(H31="","",Parâmetros!$B$5-H31) -> 136 | K31: =INDEX(Parâmetros!$D$13:$D$19,MATCH(E31,Parâmetros!$A$13:$A$19,0)) -> 43 | L31: =IF(G31="Prospecting",Parâmetros!$B$9,IF(J31>Parâmetros!$B$6,0,INDEX(Parâmetros!$C$24:$C$26,MATCH(J31,Parâmetros!$A$24:$A$26,1)))) -> 40 | M31: =IF(G31="Prospecting",1,INDEX(Parâmetros!$C$32:$C$35,MATCH(J31,Parâmetros!$A$32:$A$35,1))) -> 1 | N31: =ROUND((K31+L31)*M31,0) -> 83 | O31: =IF(AND(G31="Engaging",J31>Parâmetros!$B$6),"Sim","Não") -> Não | P31: =IF(O31="Sim","R",IF(N31>=Parâmetros!$B$39,"A",IF(N31>=Parâmetros!$B$40,"B",IF(N31>=Parâmetros!$B$41,"C","D")))) -> A | Q31: =IF(F31="","Completar cadastro","") -> Completar cadastro | R31: =INDEX(Parâmetros!$D$39:$D$43,MATCH(P31,Parâmetros!$A$39:$A$43,0)) -> Prioridade máxima: próximo passo em até 48h
A32: X9L0T199 | B32: Kami Bicknell | C32: Summer Sewald | D32: West | E32: GTX Pro | G32: Engaging | H32: 42965 | I32: =INDEX(Parâmetros!$C$13:$C$19,MATCH(E32,Parâmetros!$A$13:$A$19,0)) -> 4821 | J32: =IF(H32="","",Parâmetros!$B$5-H32) -> 135 | K32: =INDEX(Parâmetros!$D$13:$D$19,MATCH(E32,Parâmetros!$A$13:$A$19,0)) -> 43 | L32: =IF(G32="Prospecting",Parâmetros!$B$9,IF(J32>Parâmetros!$B$6,0,INDEX(Parâmetros!$C$24:$C$26,MATCH(J32,Parâmetros!$A$24:$A$26,1)))) -> 40 | M32: =IF(G32="Prospecting",1,INDEX(Parâmetros!$C$32:$C$35,MATCH(J32,Parâmetros!$A$32:$A$35,1))) -> 1 | N32: =ROUND((K32+L32)*M32,0) -> 83 | O32: =IF(AND(G32="Engaging",J32>Parâmetros!$B$6),"Sim","Não") -> Não | P32: =IF(O32="Sim","R",IF(N32>=Parâmetros!$B$39,"A",IF(N32>=Parâmetros!$B$40,"B",IF(N32>=Parâmetros!$B$41,"C","D")))) -> A | Q32: =IF(F32="","Completar cadastro","") -> Completar cadastro | R32: =INDEX(Parâmetros!$D$39:$D$43,MATCH(P32,Parâmetros!$A$39:$A$43,0)) -> Prioridade máxima: próximo passo em até 48h
A33: TUKHDOGS | B33: Maureen Marcano | C33: Summer Sewald | D33: West | E33: GTX Pro | G33: Engaging | H33: 42967 | I33: =INDEX(Parâmetros!$C$13:$C$19,MATCH(E33,Parâmetros!$A$13:$A$19,0)) -> 4821 | J33: =IF(H33="","",Parâmetros!$B$5-H33) -> 133 | K33: =INDEX(Parâmetros!$D$13:$D$19,MATCH(E33,Parâmetros!$A$13:$A$19,0)) -> 43 | L33: =IF(G33="Prospecting",Parâmetros!$B$9,IF(J33>Parâmetros!$B$6,0,INDEX(Parâmetros!$C$24:$C$26,MATCH(J33,Parâmetros!$A$24:$A$26,1)))) -> 40 | M33: =IF(G33="Prospecting",1,INDEX(Parâmetros!$C$32:$C$35,MATCH(J33,Parâmetros!$A$32:$A$35,1))) -> 1 | N33: =ROUND((K33+L33)*M33,0) -> 83 | O33: =IF(AND(G33="Engaging",J33>Parâmetros!$B$6),"Sim","Não") -> Não | P33: =IF(O33="Sim","R",IF(N33>=Parâmetros!$B$39,"A",IF(N33>=Parâmetros!$B$40,"B",IF(N33>=Parâmetros!$B$41,"C","D")))) -> A | Q33: =IF(F33="","Completar cadastro","") -> Completar cadastro | R33: =INDEX(Parâmetros!$D$39:$D$43,MATCH(P33,Parâmetros!$A$39:$A$43,0)) -> Prioridade máxima: próximo passo em até 48h
A34: TM70L0W8 | B34: Zane Levy | C34: Summer Sewald | D34: West | E34: GTX Pro | G34: Engaging | H34: 42969 | I34: =INDEX(Parâmetros!$C$13:$C$19,MATCH(E34,Parâmetros!$A$13:$A$19,0)) -> 4821 | J34: =IF(H34="","",Parâmetros!$B$5-H34) -> 131 | K34: =INDEX(Parâmetros!$D$13:$D$19,MATCH(E34,Parâmetros!$A$13:$A$19,0)) -> 43 | L34: =IF(G34="Prospecting",Parâmetros!$B$9,IF(J34>Parâmetros!$B$6,0,INDEX(Parâmetros!$C$24:$C$26,MATCH(J34,Parâmetros!$A$24:$A$26,1)))) -> 40 | M34: =IF(G34="Prospecting",1,INDEX(Parâmetros!$C$32:$C$35,MATCH(J34,Parâmetros!$A$32:$A$35,1))) -> 1 | N34: =ROUND((K34+L34)*M34,0) -> 83 | O34: =IF(AND(G34="Engaging",J34>Parâmetros!$B$6),"Sim","Não") -> Não | P34: =IF(O34="Sim","R",IF(N34>=Parâmetros!$B$39,"A",IF(N34>=Parâmetros!$B$40,"B",IF(N34>=Parâmetros!$B$41,"C","D")))) -> A | Q34: =IF(F34="","Completar cadastro","") -> Completar cadastro | R34: =INDEX(Parâmetros!$D$39:$D$43,MATCH(P34,Parâmetros!$A$39:$A$43,0)) -> Prioridade máxima: próximo passo em até 48h
A35: S53EVWFC | B35: Daniell Hammack | C35: Rocco Neubert | D35: East | E35: GTX Pro | G35: Engaging | H35: 42970 | I35: =INDEX(Parâmetros!$C$13:$C$19,MATCH(E35,Parâmetros!$A$13:$A$19,0)) -> 4821 | J35: =IF(H35="","",Parâmetros!$B$5-H35) -> 130 | K35: =INDEX(Parâmetros!$D$13:$D$19,MATCH(E35,Parâmetros!$A$13:$A$19,0)) -> 43 | L35: =IF(G35="Prospecting",Parâmetros!$B$9,IF(J35>Parâmetros!$B$6,0,INDEX(Parâmetros!$C$24:$C$26,MATCH(J35,Parâmetros!$A$24:$A$26,1)))) -> 40 | M35: =IF(G35="Prospecting",1,INDEX(Parâmetros!$C$32:$C$35,MATCH(J35,Parâmetros!$A$32:$A$35,1))) -> 1 | N35: =ROUND((K35+L35)*M35,0) -> 83 | O35: =IF(AND(G35="Engaging",J35>Parâmetros!$B$6),"Sim","Não") -> Não | P35: =IF(O35="Sim","R",IF(N35>=Parâmetros!$B$39,"A",IF(N35>=Parâmetros!$B$40,"B",IF(N35>=Parâmetros!$B$41,"C","D")))) -> A | Q35: =IF(F35="","Completar cadastro","") -> Completar cadastro | R35: =INDEX(Parâmetros!$D$39:$D$43,MATCH(P35,Parâmetros!$A$39:$A$43,0)) -> Prioridade máxima: próximo passo em até 48h
A36: QKW7MDJK | B36: Violet Mclelland | C36: Cara Losch | D36: East | E36: GTX Pro | G36: Engaging | H36: 42970 | I36: =INDEX(Parâmetros!$C$13:$C$19,MATCH(E36,Parâmetros!$A$13:$A$19,0)) -> 4821 | J36: =IF(H36="","",Parâmetros!$B$5-H36) -> 130 | K36: =INDEX(Parâmetros!$D$13:$D$19,MATCH(E36,Parâmetros!$A$13:$A$19,0)) -> 43 | L36: =IF(G36="Prospecting",Parâmetros!$B$9,IF(J36>Parâmetros!$B$6,0,INDEX(Parâmetros!$C$24:$C$26,MATCH(J36,Parâmetros!$A$24:$A$26,1)))) -> 40 | M36: =IF(G36="Prospecting",1,INDEX(Parâmetros!$C$32:$C$35,MATCH(J36,Parâmetros!$A$32:$A$35,1))) -> 1 | N36: =ROUND((K36+L36)*M36,0) -> 83 | O36: =IF(AND(G36="Engaging",J36>Parâmetros!$B$6),"Sim","Não") -> Não | P36: =IF(O36="Sim","R",IF(N36>=Parâmetros!$B$39,"A",IF(N36>=Parâmetros!$B$40,"B",IF(N36>=Parâmetros!$B$41,"C","D")))) -> A | Q36: =IF(F36="","Completar cadastro","") -> Completar cadastro | R36: =INDEX(Parâmetros!$D$39:$D$43,MATCH(P36,Parâmetros!$A$39:$A$43,0)) -> Prioridade máxima: próximo passo em até 48h
A37: UIOJX7O0 | B37: Cassey Cress | C37: Rocco Neubert | D37: East | E37: GTX Pro | G37: Engaging | H37: 42971 | I37: =INDEX(Parâmetros!$C$13:$C$19,MATCH(E37,Parâmetros!$A$13:$A$19,0)) -> 4821 | J37: =IF(H37="","",Parâmetros!$B$5-H37) -> 129 | K37: =INDEX(Parâmetros!$D$13:$D$19,MATCH(E37,Parâmetros!$A$13:$A$19,0)) -> 43 | L37: =IF(G37="Prospecting",Parâmetros!$B$9,IF(J37>Parâmetros!$B$6,0,INDEX(Parâmetros!$C$24:$C$26,MATCH(J37,Parâmetros!$A$24:$A$26,1)))) -> 40 | M37: =IF(G37="Prospecting",1,INDEX(Parâmetros!$C$32:$C$35,MATCH(J37,Parâmetros!$A$32:$A$35,1))) -> 1 | N37: =ROUND((K37+L37)*M37,0) -> 83 | O37: =IF(AND(G37="Engaging",J37>Parâmetros!$B$6),"Sim","Não") -> Não | P37: =IF(O37="Sim","R",IF(N37>=Parâmetros!$B$39,"A",IF(N37>=Parâmetros!$B$40,"B",IF(N37>=Parâmetros!$B$41,"C","D")))) -> A | Q37: =IF(F37="","Completar cadastro","") -> Completar cadastro | R37: =INDEX(Parâmetros!$D$39:$D$43,MATCH(P37,Parâmetros!$A$39:$A$43,0)) -> Prioridade máxima: próximo passo em até 48h
A38: Z8Z77GN3 | B38: Kami Bicknell | C38: Summer Sewald | D38: West | E38: GTX Pro | G38: Engaging | H38: 42971 | I38: =INDEX(Parâmetros!$C$13:$C$19,MATCH(E38,Parâmetros!$A$13:$A$19,0)) -> 4821 | J38: =IF(H38="","",Parâmetros!$B$5-H38) -> 129 | K38: =INDEX(Parâmetros!$D$13:$D$19,MATCH(E38,Parâmetros!$A$13:$A$19,0)) -> 43 | L38: =IF(G38="Prospecting",Parâmetros!$B$9,IF(J38>Parâmetros!$B$6,0,INDEX(Parâmetros!$C$24:$C$26,MATCH(J38,Parâmetros!$A$24:$A$26,1)))) -> 40 | M38: =IF(G38="Prospecting",1,INDEX(Parâmetros!$C$32:$C$35,MATCH(J38,Parâmetros!$A$32:$A$35,1))) -> 1 | N38: =ROUND((K38+L38)*M38,0) -> 83 | O38: =IF(AND(G38="Engaging",J38>Parâmetros!$B$6),"Sim","Não") -> Não | P38: =IF(O38="Sim","R",IF(N38>=Parâmetros!$B$39,"A",IF(N38>=Parâmetros!$B$40,"B",IF(N38>=Parâmetros!$B$41,"C","D")))) -> A | Q38: =IF(F38="","Completar cadastro","") -> Completar cadastro | R38: =INDEX(Parâmetros!$D$39:$D$43,MATCH(P38,Parâmetros!$A$39:$A$43,0)) -> Prioridade máxima: próximo passo em até 48h
A39: TLLW2ZRM | B39: Zane Levy | C39: Summer Sewald | D39: West | E39: GTX Pro | F39: Condax | G39: Engaging | H39: 42972 | I39: =INDEX(Parâmetros!$C$13:$C$19,MATCH(E39,Parâmetros!$A$13:$A$19,0)) -> 4821 | J39: =IF(H39="","",Parâmetros!$B$5-H39) -> 128 | K39: =INDEX(Parâmetros!$D$13:$D$19,MATCH(E39,Parâmetros!$A$13:$A$19,0)) -> 43 | L39: =IF(G39="Prospecting",Parâmetros!$B$9,IF(J39>Parâmetros!$B$6,0,INDEX(Parâmetros!$C$24:$C$26,MATCH(J39,Parâmetros!$A$24:$A$26,1)))) -> 40 | M39: =IF(G39="Prospecting",1,INDEX(Parâmetros!$C$32:$C$35,MATCH(J39,Parâmetros!$A$32:$A$35,1))) -> 1 | N39: =ROUND((K39+L39)*M39,0) -> 83 | O39: =IF(AND(G39="Engaging",J39>Parâmetros!$B$6),"Sim","Não") -> Não | P39: =IF(O39="Sim","R",IF(N39>=Parâmetros!$B$39,"A",IF(N39>=Parâmetros!$B$40,"B",IF(N39>=Parâmetros!$B$41,"C","D")))) -> A | Q39: =IF(F39="","Completar cadastro","") | R39: =INDEX(Parâmetros!$D$39:$D$43,MATCH(P39,Parâmetros!$A$39:$A$43,0)) -> Prioridade máxima: próximo passo em até 48h
A40: RU5X1LZM | B40: Zane Levy | C40: Summer Sewald | D40: West | E40: GTX Pro | G40: Engaging | H40: 42973 | I40: =INDEX(Parâmetros!$C$13:$C$19,MATCH(E40,Parâmetros!$A$13:$A$19,0)) -> 4821 | J40: =IF(H40="","",Parâmetros!$B$5-H40) -> 127 | K40: =INDEX(Parâmetros!$D$13:$D$19,MATCH(E40,Parâmetros!$A$13:$A$19,0)) -> 43 | L40: =IF(G40="Prospecting",Parâmetros!$B$9,IF(J40>Parâmetros!$B$6,0,INDEX(Parâmetros!$C$24:$C$26,MATCH(J40,Parâmetros!$A$24:$A$26,1)))) -> 40 | M40: =IF(G40="Prospecting",1,INDEX(Parâmetros!$C$32:$C$35,MATCH(J40,Parâmetros!$A$32:$A$35,1))) -> 1 | N40: =ROUND((K40+L40)*M40,0) -> 83 | O40: =IF(AND(G40="Engaging",J40>Parâmetros!$B$6),"Sim","Não") -> Não | P40: =IF(O40="Sim","R",IF(N40>=Parâmetros!$B$39,"A",IF(N40>=Parâmetros!$B$40,"B",IF(N40>=Parâmetros!$B$41,"C","D")))) -> A | Q40: =IF(F40="","Completar cadastro","") -> Completar cadastro | R40: =INDEX(Parâmetros!$D$39:$D$43,MATCH(P40,Parâmetros!$A$39:$A$43,0)) -> Prioridade máxima: próximo passo em até 48h
...

Sheet Histórico
A1: ID | B1: Vendedor | C1: Produto | D1: Conta | E1: Estágio | F1: Data engajamento | G1: Data fechamento | H1: Dias de ciclo | I1: Ganho (1/0)
A2: 1C1I7A6R | B2: Moses Frase | C2: GTX Plus Basic | D2: Cancity | E2: Won | F2: 42663 | G2: 42795 | H2: =G2-F2 -> 132 | I2: =IF(E2="Won",1,0) -> 1
A3: N4SD17JR | B3: Reed Clapper | C3: GTX Basic | D3: Acme Corporation | E3: Won | F3: 42686 | G3: 42795 | H3: =G3-F3 -> 109 | I3: =IF(E3="Won",1,0) -> 1
A4: PQ2VF873 | B4: Zane Levy | C4: GTX Pro | D4: Zoomit | E4: Lost | F4: 42780 | G4: 42795 | H4: =G4-F4 -> 15 | I4: =IF(E4="Won",1,0) -> 0
A5: WS9CXY7E | B5: Gladys Colclough | C5: GTX Plus Pro | D5: Conecom | E5: Won | F5: 42782 | G5: 42795 | H5: =G5-F5 -> 13 | I5: =IF(E5="Won",1,0) -> 1
A6: Q7IRUJK7 | B6: Anna Snelling | C6: GTX Plus Pro | D6: Codehow | E6: Won | F6: 42736 | G6: 42795 | H6: =G6-F6 -> 59 | I6: =IF(E6="Won",1,0) -> 1
A7: 8O9V7UOZ | B7: Anna Snelling | C7: MG Special | D7: Rundofase | E7: Won | F7: 42744 | G7: 42795 | H7: =G7-F7 -> 51 | I7: =IF(E7="Won",1,0) -> 1
A8: BXXMA7F3 | B8: Hayden Neloms | C8: MG Advanced | D8: Nam-zim | E8: Lost | F8: 42695 | G8: 42795 | H8: =G8-F8 -> 100 | I8: =IF(E8="Won",1,0) -> 0
